Workbook

Sheet Plante
A1: Cod | B1: Denumire | C1: Denumire latină | D1: Categorie | E1: Cantitate (buc.) | F1: Lumină | G1: Înălțime la maturitate | H1: Zonă irigare | I1: Doză vară (l/plantă) | J1: Frecvență vară (udări/săpt.) | K1: Consum săptămânal vara (l) | L1: Puncte marcate pe plan | M1: Observații
A2: A28 | B2: Arborele de lalea | C2: Liriodendron tulipifera | D2: Arbore | E2: 1 | F2: Soare plin (min. 6 h) | G2: 25–30 m | H2: D | I2: 30 | J2: 2 | K2: =E2*I2*J2 | L2: 1
A3: A11 | B3: Arborele de mătase | C3: Albizia julibrissin | D3: Arbore | E3: 1 | F3: Soare plin (min. 6 h) | G3: 6–9 m | H3: D | I3: 15 | J3: 2 | K3: =E3*I3*J3 | L3: 1
A4: A24 | B4: Frasin | C4: Fraxinus excelsior | D4: Arbore | E4: 17 | F4: Soare–semiumbră | G4: 25–30 m | H4: D | I4: 30 | J4: 2 | K4: =E4*I4*J4 | L4: 17
A5: A30 | B5: Magnolie | C5: Magnolia × soulangiana | D5: Arbore | E5: 1 | F5: Soare–semiumbră | G5: 6–8 m | H5: D | I5: 20 | J5: 2 | K5: =E5*I5*J5 | L5: 1
A6: A5 | B6: Paltin de câmp | C6: Acer platanoides | D6: Arbore | E6: 2 | F6: Soare–semiumbră | G6: 20–25 m | H6: D | I6: 25 | J6: 2 | K6: =E6*I6*J6 | L6: 2
A7: A34 | B7: Pin negru | C7: Pinus nigra | D7: Arbore | E7: 20 | F7: Soare plin (min. 6 h) | G7: 20–30 m | H7: X | I7: 5 | J7: 1 | K7: =E7*I7*J7 | L7: 21 | M7: Pe plan sunt 21 de simboluri față de 20 în legendă — de verificat la trasare.
A8: A43 | B8: Salcie plângătoare | C8: Salix babylonica | D8: Arbore | E8: 2 | F8: Soare plin (min. 6 h) | G8: 10–12 m | H8: D | I8: 40 | J8: 2 | K8: =E8*I8*J8 | L8: 2
A9: A40 | B9: Stejar pufos | C9: Quercus pubescens | D9: Arbore | E9: 1 | F9: Soare plin (min. 6 h) | G9: 10–15 m | H9: D | I9: 15 | J9: 2 | K9: =E9*I9*J9 | L9: 1
A10: A21 | B10: Sălcioară | C10: Elaeagnus angustifolia | D10: Arbore | E10: 32 | F10: Soare plin (min. 6 h) | G10: 6–8 m | H10: B | I10: 5 | J10: 1 | K10: =E10*I10*J10 | L10: 32
A11: A48 | B11: Tei argintiu | C11: Tilia tomentosa | D11: Arbore | E11: 1 | F11: Soare–semiumbră | G11: 25–30 m | H11: D | I11: 30 | J11: 2 | K11: =E11*I11*J11 | L11: 1
A12: A52 | B12: Ulm de Turkestan | C12: Ulmus pumila | D12: Arbore | E12: 951 | F12: Soare plin (min. 6 h) | G12: 12–15 m | H12: X | I12: 5 | J12: 1 | K12: =E12*I12*J12 | L12: 2 | M12: Perdeaua forestieră dinspre crivăț: desenată ca aliniament, nu ca simboluri individuale (2 puncte pe plan).
A13: F32 | B13: Agriș | C13: Ribes uva-crispa | D13: Fructifer | E13: 2 | F13: Soare–semiumbră | G13: 1,5 m | H13: F | I13: 5 | J13: 2 | K13: =E13*I13*J13 | L13: 2
A14: F1 | B14: Alun | C14: Corylus avellana | D14: Fructifer | E14: 12 | F14: Soare–semiumbră | G14: 4–5 m | H14: F | I14: 15 | J14: 2 | K14: =E14*I14*J14 | L14: 12
A15: F34 | B15: Arbore de mazăre | C15: Caragana arborescens | D15: Fructifer | E15: 3 | F15: Soare plin (min. 6 h) | G15: 4–6 m | H15: A | I15: 5 | J15: 1 | K15: =E15*I15*J15 | L15: 3
A16: F59 | B16: Aronia | C16: Aronia melanocarpa | D16: Fructifer | E16: 3 | F16: Soare–semiumbră | G16: 2,0–2,5 m | H16: C | I16: 8 | J16: 2 | K16: =E16*I16*J16 | L16: 3
A17: F10 | B17: Cireș | C17: Prunus avium | D17: Fructifer | E17: 1 | F17: Soare plin (min. 6 h) | G17: 6–9 m | H17: E | I17: 30 | J17: 2 | K17: =E17*I17*J17 | L17: 1
A18: F31 | B18: Coacăz alb | C18: Ribes rubrum (varietatea albă) | D18: Fructifer | E18: 2 | F18: Soare–semiumbră | G18: 1,5 m | H18: F | I18: 5 | J18: 2 | K18: =E18*I18*J18 | L18: 2
A19: F30 | B19: Coacăz negru | C19: Ribes nigrum | D19: Fructifer | E19: 3 | F19: Soare–semiumbră | G19: 1,8–2,0 m | H19: F | I19: 5 | J19: 2 | K19: =E19*I19*J19 | L19: 3
A20: F29 | B20: Coacăz roșu | C20: Ribes rubrum | D20: Fructifer | E20: 16 | F20: Soare–semiumbră | G20: 1,5 m | H20: F | I20: 5 | J20: 2 | K20: =E20*I20*J20 | L20: 16
A21: F11 | B21: Corcoduș | C21: Prunus cerasifera | D21: Fructifer | E21: 1 | F21: Soare plin (min. 6 h) | G21: 6–8 m | H21: E | I21: 20 | J21: 2 | K21: =E21*I21*J21 | L21: 1
A22: F21 | B22: Corn | C22: Cornus mas | D22: Fructifer | E22: 14 | F22: Soare–semiumbră | G22: 5–6 m | H22: F | I22: 10 | J22: 2 | K22: =E22*I22*J22 | L22: 14
A23: F26 | B23: Cătină | C23: Hippophae rhamnoides | D23: Fructifer | E23: 5 | F23: Soare plin (min. 6 h) | G23: 4–6 m | H23: F | I23: 3 | J23: 2 | K23: =E23*I23*J23 | L23: 5
A24: F9 | B24: Dud alb | C24: Morus alba | D24: Fructifer | E24: 16 | F24: Soare plin (min. 6 h) | G24: 10–12 m | H24: D | I24: 20 | J24: 2 | K24: =E24*I24*J24 | L24: 16
... A36: F17 | B36: Păr | C36: Pyrus communis | D36: Fructifer | E36: 1 | F36: Soare plin (min. 6 h) | G36: 6–10 m | H36: E | I36: 25 | J36: 2 | K36: =E36*I36*J36 | L36: 1
A37: F16 | B37: Rodiu | C37: Punica granatum | D37: Fructifer | E37: 1 | F37: Soare plin (min. 6 h) | G37: 3–4 m | H37: E | I37: 15 | J37: 2 | K37: =E37*I37*J37 | L37: 1 | M37: La limita de rezistență la ger: primii ani cere protecție iarna.
A38: F4 | B38: Smochin | C38: Ficus carica | D38: Fructifer | E38: 2 | F38: Soare plin (min. 6 h) | G38: 4–6 m | H38: E | I38: 20 | J38: 2 | K38: =E38*I38*J38 | L38: 2
A39: F44 | B39: Sânger | C39: Cornus sanguinea | D39: Fructifer | E39: 2 | F39: Soare–semiumbră | G39: 4–5 m | H39: C | I39: 8 | J39: 2 | K39: =E39*I39*J39 | L39: 2
A40: F12 | B40: Vișin | C40: Prunus cerasus | D40: Fructifer | E40: 1 | F40: Soare plin (min. 6 h) | G40: 4–5 m | H40: E | I40: 20 | J40: 2 | K40: =E40*I40*J40 | L40: 1
A41: F33 | B41: Viță de vie | C41: Vitis vinifera | D41: Fructifer | E41: 15 | F41: Soare plin (min. 6 h) | G41: 2,0–2,5 m | H41: E | I41: 15 | J41: 2 | K41: =E41*I41*J41 | L41: 5 | M41: Rând pe spalier: 5 simboluri pe plan pentru 15 butuci.
A42: S38 | B42: Cununiță | C42: Spiraea japonica | D42: Arbust | E42: 3 | F42: Soare plin (min. 6 h) | G42: 1,2–1,5 m | H42: C | I42: 4 | J42: 2 | K42: =E42*I42*J42 | L42: 3
A43: S72 | B43: Călin | C43: Viburnum opulus | D43: Arbust | E43: 4 | F43: Soare–semiumbră | G43: 4–5 m | H43: C | I43: 10 | J43: 2 | K43: =E43*I43*J43 | L43: 3 | M43: Pe plan sunt 3 simboluri față de 4 în legendă — de verificat la trasare.
A44: S6 | B44: Hibiscus | C44: Hibiscus syriacus | D44: Arbust | E44: 9 | F44: Soare plin (min. 6 h) | G44: 3–4 m | H44: C | I44: 8 | J44: 2 | K44: =E44*I44*J44 | L44: 9
A45: S3 | B45: Iasomie falsă | C45: Philadelphus coronarius | D45: Arbust | E45: 4 | F45: Soare–semiumbră | G45: 3,0 m | H45: C | I45: 8 | J45: 2 | K45: =E45*I45*J45 | L45: 4
A46: S50 | B46: Kerria | C46: Kerria japonica | D46: Arbust | E46: 8 | F46: Semiumbră–umbră | G46: 2,0–2,5 m | H46: C | I46: 5 | J46: 2 | K46: =E46*I46*J46 | L46: 8
A47: S34 | B47: Lemn câinesc | C47: Ligustrum ovalifolium | D47: Arbust | E47: 168 | F47: Soare–semiumbră | G47: 3–4 m | H47: B | I47: 5 | J47: 1 | K47: =E47*I47*J47 | L47: 0 | M47: Gard viu: desenat ca linie continuă, fără simbol pentru fiecare exemplar.
A48: S21 | B48: Liliac | C48: Syringa vulgaris | D48: Arbust | E48: 2 | F48: Soare plin (min. 6 h) | G48: 4–5 m | H48: C | I48: 10 | J48: 2 | K48: =E48*I48*J48 | L48: 2
A49: S80 | B49: Liliac de vară | C49: Buddleja davidii | D49: Arbust | E49: 6 | F49: Soare plin (min. 6 h) | G49: 2,5–3,0 m | H49: C | I49: 8 | J49: 2 | K49: =E49*I49*J49 | L49: 6
A50: S17 | B50: Oțetar | C50: Rhus typhina | D50: Arbust | E50: 1 | F50: Soare plin (min. 6 h) | G50: 4–5 m | H50: A | I50: 8 | J50: 1 | K50: =E50*I50*J50 | L50: 1 | M50: Drajonează agresiv: cere limitator de rădăcină.
A51: S11 | B51: Photinia | C51: Photinia × fraseri | D51: Arbust | E51: 76 | F51: Soare–semiumbră | G51: 3–4 m | H51: B | I51: 8 | J51: 1 | K51: =E51*I51*J51 | L51: 0 | M51: Gard viu: desenat ca linie continuă, fără simbol pentru fiecare exemplar.
...

Sheet Sinteză
A1: Sinteză pe categorii
A3: Categorie | B3: Specii | C3: Cantitate (buc.) | D3: Pondere | E3: Consum săptămânal vara (l)
A4: Arbore | B4: =COUNTIF(Plante!$D$2:$D$66,$A4) | C4: =SUMIF(Plante!$D$2:$D$66,$A4,Plante!$E$2:$E$66) | D4: =IFERROR($C4/$C$9,0) | E4: =SUMIF(Plante!$D$2:$D$66,$A4,Plante!$K$2:$K$66)
A5: Fructifer | B5: =COUNTIF(Plante!$D$2:$D$66,$A5) | C5: =SUMIF(Plante!$D$2:$D$66,$A5,Plante!$E$2:$E$66) | D5: =IFERROR($C5/$C$9,0) | E5: =SUMIF(Plante!$D$2:$D$66,$A5,Plante!$K$2:$K$66)
A6: Arbust | B6: =COUNTIF(Plante!$D$2:$D$66,$A6) | C6: =SUMIF(Plante!$D$2:$D$66,$A6,Plante!$E$2:$E$66) | D6: =IFERROR($C6/$C$9,0) | E6: =SUMIF(Plante!$D$2:$D$66,$A6,Plante!$K$2:$K$66)
A7: Aromatică | B7: =COUNTIF(Plante!$D$2:$D$66,$A7) | C7: =SUMIF(Plante!$D$2:$D$66,$A7,Plante!$E$2:$E$66) | D7: =IFERROR($C7/$C$9,0) | E7: =SUMIF(Plante!$D$2:$D$66,$A7,Plante!$K$2:$K$66)
A8: Ierbacee | B8: =COUNTIF(Plante!$D$2:$D$66,$A8) | C8: =SUMIF(Plante!$D$2:$D$66,$A8,Plante!$E$2:$E$66) | D8: =IFERROR($C8/$C$9,0) | E8: =SUMIF(Plante!$D$2:$D$66,$A8,Plante!$K$2:$K$66)
A9: Total | B9: =SUM(B4:B8) | C9: =SUM(C4:C8) | D9: =IFERROR($C9/$C9,0) | E9: =SUM(E4:E8)
A11: Sinteză pe cerința de lumină
A12: Cerință de lumină | B12: Specii | C12: Cantitate (buc.) | D12: Pondere | E12: Consum săptămânal vara (l)
A13: Soare plin (min. 6 h) | B13: =COUNTIF(Plante!$F$2:$F$66,$A13) | C13: =SUMIF(Plante!$F$2:$F$66,$A13,Plante!$E$2:$E$66) | D13: =IFERROR($C13/$C$16,0) | E13: =SUMIF(Plante!$F$2:$F$66,$A13,Plante!$K$2:$K$66)
A14: Soare–semiumbră | B14: =COUNTIF(Plante!$F$2:$F$66,$A14) | C14: =SUMIF(Plante!$F$2:$F$66,$A14,Plante!$E$2:$E$66) | D14: =IFERROR($C14/$C$16,0) | E14: =SUMIF(Plante!$F$2:$F$66,$A14,Plante!$K$2:$K$66)
A15: Semiumbră–umbră | B15: =COUNTIF(Plante!$F$2:$F$66,$A15) | C15: =SUMIF(Plante!$F$2:$F$66,$A15,Plante!$E$2:$E$66) | D15: =IFERROR($C15/$C$16,0) | E15: =SUMIF(Plante!$F$2:$F$66,$A15,Plante!$K$2:$K$66)
A16: Total | B16: =SUM(B13:B15) | C16: =SUM(C13:C15) | D16: =IFERROR($C16/$C16,0) | E16: =SUM(E13:E15)

Sheet Irigare pe zone
A1: Zone de irigare prin picurare
A2: Dozele sunt cele de vară, pentru plante intrate pe rod. Vezi fila Note pentru regimul din primii doi ani.
A4: Zonă | B4: Descriere | C4: Tub · lungime | D4: Specii | E4: Cantitate (buc.) | F4: Consum la o udare (l) | G4: Udări/săpt. | H4: Consum săptămânal (l)
A5: A | B5: Aromatice și specii rezistente la secetă | C5: T6 · 100 m | D5: =COUNTIF(Plante!$H$2:$H$66,$A5) | E5: =SUMIF(Plante!$H$2:$H$66,$A5,Plante!$E$2:$E$66) | F5: =SUMPRODUCT((Plante!$H$2:$H$66=$A5)*Plante!$E$2:$E$66*Plante!$I$2:$I$66) | G5: =IFERROR(ROUND($H5/$F5,0),0) | H5: =SUMIF(Plante!$H$2:$H$66,$A5,Plante!$K$2:$K$66)
A6: B | B6: Garduri vii — lemn câinesc, photinia, sălcioară | C6: T1+T3 · 200+150 m | D6: =COUNTIF(Plante!$H$2:$H$66,$A6) | E6: =SUMIF(Plante!$H$2:$H$66,$A6,Plante!$E$2:$E$66) | F6: =SUMPRODUCT((Plante!$H$2:$H$66=$A6)*Plante!$E$2:$E$66*Plante!$I$2:$I$66) | G6: =IFERROR(ROUND($H6/$F6,0),0) | H6: =SUMIF(Plante!$H$2:$H$66,$A6,Plante!$K$2:$K$66)
A7: C | B7: Arbuști ornamentali | C7: T4 · 150 m | D7: =COUNTIF(Plante!$H$2:$H$66,$A7) | E7: =SUMIF(Plante!$H$2:$H$66,$A7,Plante!$E$2:$E$66) | F7: =SUMPRODUCT((Plante!$H$2:$H$66=$A7)*Plante!$E$2:$E$66*Plante!$I$2:$I$66) | G7: =IFERROR(ROUND($H7/$F7,0),0) | H7: =SUMIF(Plante!$H$2:$H$66,$A7,Plante!$K$2:$K$66)
A8: D | B8: Arbori mari | C8: T2 · 180 m | D8: =COUNTIF(Plante!$H$2:$H$66,$A8) | E8: =SUMIF(Plante!$H$2:$H$66,$A8,Plante!$E$2:$E$66) | F8: =SUMPRODUCT((Plante!$H$2:$H$66=$A8)*Plante!$E$2:$E$66*Plante!$I$2:$I$66) | G8: =IFERROR(ROUND($H8/$F8,0),0) | H8: =SUMIF(Plante!$H$2:$H$66,$A8,Plante!$K$2:$K$66)
A9: E | B9: Fructiferi și viță de vie | C9: T5 · 120 m | D9: =COUNTIF(Plante!$H$2:$H$66,$A9) | E9: =SUMIF(Plante!$H$2:$H$66,$A9,Plante!$E$2:$E$66) | F9: =SUMPRODUCT((Plante!$H$2:$H$66=$A9)*Plante!$E$2:$E$66*Plante!$I$2:$I$66) | G9: =IFERROR(ROUND($H9/$F9,0),0) | H9: =SUMIF(Plante!$H$2:$H$66,$A9,Plante!$K$2:$K$66)
A10: F | B10: Fructe mici — coacăze, corn, alun | C10: T6 extins · 100 m | D10: =COUNTIF(Plante!$H$2:$H$66,$A10) | E10: =SUMIF(Plante!$H$2:$H$66,$A10,Plante!$E$2:$E$66) | F10: =SUMPRODUCT((Plante!$H$2:$H$66=$A10)*Plante!$E$2:$E$66*Plante!$I$2:$I$66) | G10: =IFERROR(ROUND($H10/$F10,0),0) | H10: =SUMIF(Plante!$H$2:$H$66,$A10,Plante!$K$2:$K$66)
A11: X | B11: Ulmi și pini, în perioada de stabilire | C11: rotație, separat | D11: =COUNTIF(Plante!$H$2:$H$66,$A11) | E11: =SUMIF(Plante!$H$2:$H$66,$A11,Plante!$E$2:$E$66) | F11: =SUMPRODUCT((Plante!$H$2:$H$66=$A11)*Plante!$E$2:$E$66*Plante!$I$2:$I$66) | G11: =IFERROR(ROUND($H11/$F11,0),0) | H11: =SUMIF(Plante!$H$2:$H$66,$A11,Plante!$K$2:$K$66)
A12: Total | D12: =SUM(D5:D11) | E12: =SUM(E5:E11) | F12: =SUM(F5:F11) | H12: =SUM(H5:H11)

Sheet Note
A1: Plante și cantități — amenajare Crucea, județul Constanța
A3: Ce conține
A4: Fila „Plante" listează toate speciile din proiect, cu cantitatea de plantat. Filele „Sinteză" și „Irigare pe zone" nu conțin date proprii: totalurile lor sunt formule peste fila „Plante", deci se actualizează singure dacă modifici o cantitate.
A6: De unde vin cantitățile
A7: Coloana „Cantitate (buc.)" e preluată din legenda planului peisager (fișierul DWG), aceeași sursă folosită și de planul de irigare din proiect. Coloana „Puncte marcate pe plan" arată câte simboluri are specia în pozitie.json, fișierul care alimentează planul interactiv.
A8: Pentru 59 din cele 65 de specii, cele două coloane coincid. Cele 6 diferențe sunt explicate în coloana „Observații" și au două cauze: aliniamentele și gardurile vii sunt desenate ca linii continue, nu ca simbol pentru fiecare exemplar (ulm, lemn câinesc, photinia, viță de vie), iar la pinul negru și călin numărul de simboluri diferă cu unu față de legendă — de verificat la trasarea în teren.
A10: Udarea
A11: Doza și frecvența sunt cele de vară, pentru plante intrate pe rod, exact ca în planul de irigare prin picurare. „Consum săptămânal vara" = cantitate × doză × frecvență.
A12: În primii doi ani, cât rădăcina e mică, regimul e mai generos: în anul 1 doza crește cu 50 % și se adaugă o udare pe săptămână, în anul 2 doza crește cu 25 % la aceeași frecvență. Primăvara și toamna se udă la jumătate din frecvență; iarna nu se udă.
A14: Ce este estimare și ce nu
A15: Cantitățile, dozele de udare și zonele de irigare vin din proiect. Înălțimea la maturitate și cerința de lumină sunt estimări pentru material de pepinieră obișnuit în clima Dobrogei, nu măsurători — la fel ca în fișele de plantă din planul interactiv.
A17: Surse
... A19: Proiect: https://bit.ly/vialunga
